Workbook

Sheet Report
A1: Province | B1: District | D1: Local Level | F1: School | H1: School Code | I1: TID | J1: Name | L1: Gender | N1: Caste | O1: Mother Tongue | Q1: Nationality | S1: Phone | T1: Date of Birth | U1: Citizenship No | V1: Teacher Type | W1: Qualification | X1: Stream | Y1: Level | Z1: Rank | AA1: Position
A2: Bagmati Province | B2: Rasuwa | D2: Gosaikunda Gaunpalika | F2: Pra V Khamging | H2: 290020002 | I2: 29002000277002 | J2: Temba Tamang | K2: t]Daf tfdfË | L2: M | M2: =IF(L2="M","k'?if","dlxnf") -> k'?if | N2: J | O2: Sherpa | P2: z]kf{ | Q2: Nepali | R2: 1 | S2: 9741016525 | T2: 2035-10-15 | U2: 4740-107 | V2: Teacher | W2: Intermediate | Y2: Lower Basic | Z2: 3rd | AA2: Permanent | AB2: :yfoL
A3: Bagmati Province | B3: Rasuwa | D3: Gosaikunda Gaunpalika | F3: Pra V Khamging | H3: 290020002 | I3: 29002000277003 | J3: Maya Sherpa | K3: dfof z]kf{ | L3: F | M3: =IF(L3="M","k'?if","dlxnf") -> dlxnf | N3: J | O3: Tamang | P3: tfdfË | Q3: Nepali | R3: 2 | S3: 9808712730 | T3: 2034-10-1 | U3: 3781 | V3: Teacher | W3: Bachelors | X3: Education | Y3: Lower Basic | Z3: 3rd | AA3: Permanent | AB3: :yfoL
A4: Bagmati Province | B4: Rasuwa | D4: Gosaikunda Gaunpalika | F4: Pra V Khamging | H4: 290020002 | I4: 29002000277001 | J4: Kabita Neupane | K4: slatf Gof}kfg] | L4: F | M4: =IF(L4="M","k'?if","dlxnf") -> dlxnf | N4: O | O4: Nepali | P4: g]kfnL | Q4: Nepali | R4: 3 | S4: 9741161789 | T4: 2042-1-18 | U4: 306 | V4: Teacher | W4: Masters | X4: Education | Y4: Lower Basic | Z4: 3rd | AA4: Temporary | AB4: c:yfoL
A5: Bagmati Province | B5: Rasuwa | D5: Gosaikunda Gaunpalika | F5: Lingling Pra V | H5: 290020003 | I5: 29002000377002 | J5: Nirmal Jang Sherpa | K5: lgd{n h+u z]kf{ | L5: M | M5: =IF(L5="M","k'?if","dlxnf") -> k'?if | N5: J | O5: Tamang | P5: tfdfË | Q5: Nepali | R5: 4 | S5: 9860228865 | T5: 2031-11-1 | U5: 3384 | V5: Teacher | W5: Masters | Y5: Lower Basic | Z5: 3rd | AA5: Permanent | AB5: :yfoL
A6: Bagmati Province | B6: Rasuwa | D6: Gosaikunda Gaunpalika | F6: Lingling Pra V | H6: 290020003 | I6: 29002000377001 | J6: Sushil Koirala | K6: ;'lzn sf]O/fnf | L6: M | M6: =IF(L6="M","k'?if","dlxnf") -> k'?if | N6: O | O6: Nepali | P6: g]kfnL | Q6: Nepali | R6: 5 | S6: 9741035103 | T6: 2025-7-3 | U6: 700 | V6: Head Teacher | W6: Bachelors | X6: Education | Y6: Lower Basic | Z6: 3rd | AA6: Permanent | AB6: :yfoL
A7: Bagmati Province | B7: Rasuwa | D7: Gosaikunda Gaunpalika | F7: Gaun Pharka Pra V | H7: 290050001 | I7: 29005000177001 | J7: Tulshingi Tamang | K7: t'lN;+uL tfdfË | L7: M | M7: =IF(L7="M","k'?if","dlxnf") -> k'?if | N7: J | O7: Tamang | P7: tfdfË | Q7: Nepali | R7: 6 | T7: 2027-1-15 | U7: 270-702 | V7: Head Teacher | W7: Intermediate | Y7: Lower Basic | Z7: 3rd | AA7: Permanent | AB7: :yfoL
A8: Bagmati Province | B8: Rasuwa | D8: Gosaikunda Gaunpalika | F8: Gaun Pharka Pra V | H8: 290050001 | I8: 29005000177005 | J8: Yuna Thokra | K8: o'gf yf]s/f | L8: F | M8: =IF(L8="M","k'?if","dlxnf") -> dlxnf | N8: J | O8: Nepali | P8: tfdfË | Q8: Nepali | R8: 7 | T8: 2052-5-17 | U8: 155 | V8: Teacher | Y8: ECD/PPC | Z8: 3rd | AA8: ECD Facilitator | AB8: O;L8L ;xof]uL
A9: Bagmati Province | B9: Rasuwa | D9: Gosaikunda Gaunpalika | F9: Gaun Pharka Pra V | H9: 290050001 | I9: 29005000177006 | J9: Urmila Lama | K9: pld{nf nfdf | L9: F | M9: =IF(L9="M","k'?if","dlxnf") -> dlxnf | N9: J | O9: Tamang | P9: tfdfË | Q9: Nepali | R9: 8 | S9: 9843404440 | T9: 2033-8-3 | U9: 3769 | V9: Teacher | W9: Intermediate | X9: Edu | Y9: Lower Basic | Z9: 3rd | AA9: Permanent | AB9: :yfoL
A10: Bagmati Province | B10: Rasuwa | D10: Gosaikunda Gaunpalika | F10: Bhimali Pra V | H10: 290050002 | I10: 29005000277008 | J10: Pema Wangmo Tamang | K10: k]df jËdf] tfdfË | L10: F | M10: =IF(L10="M","k'?if","dlxnf") -> dlxnf | N10: J | O10: Tamang | P10: tfdfË | Q10: Nepali | R10: 9 | S10: 9841903990 | T10: 2037-3-28 | U10: 5637/400 | V10: Teacher | W10: Intermediate | X10: Edu | Y10: Lower Basic | Z10: 3rd | AA10: Permanent | AB10: :yfoL
A11: Bagmati Province | B11: Rasuwa | D11: Gosaikunda Gaunpalika | F11: Bhimali Pra V | H11: 290050002 | I11: 29005000277007 | J11: Krishna Bahadur Kumal | K11: s[i0f axfb'/ s'dfn | L11: M | M11: =IF(L11="M","k'?if","dlxnf") -> k'?if | N11: J | O11: Nepali | P11: g]kfnL | Q11: Nepali | R11: 10 | T11: 2023-11-23 | U11: 424 | V11: Head Teacher | W11: SLC | Y11: Lower Basic | Z11: 3rd | AA11: Permanent | AB11: :yfoL
A12: Bagmati Province | B12: Rasuwa | D12: Gosaikunda Gaunpalika | F12: Bhimali Pra V | H12: 290050002 | I12: 29005000277006 | J12: Yuna Tamang | K12: o'gf tfdfË | L12: F | M12: =IF(L12="M","k'?if","dlxnf") -> dlxnf | N12: J | O12: Tamang | P12: tfdfË | Q12: Nepali | R12: 11 | S12: 9823756146 | T12: 2054-10-17 | U12: 23/10/72/01088 | V12: Teacher | Y12: ECD/PPC | Z12: 3rd | AA12: ECD Facilitator | AB12: O;L8L ;xof]uL
A13: Bagmati Province | B13: Rasuwa | D13: Gosaikunda Gaunpalika | F13: Saraswati Adharbhut Vidyalaya | H13: 290050003 | I13: 29005000377010 | J13: Durga Bhatta | K13: b\uf{ eQ | L13: F | M13: =IF(L13="M","k'?if","dlxnf") -> dlxnf | N13: B/C | O13: Nepali | P13: g]kfnL | Q13: Nepali | R13: 12 | T13: 2046-11-27 | U13: 113572 | V13: Teacher | W13: Bachelors | Y13: Lower Basic | Z13: 3rd | AA13: Permanent | AB13: :yfoL
A14: Bagmati Province | B14: Rasuwa | D14: Gosaikunda Gaunpalika | F14: Saraswati Adharbhut Vidyalaya | H14: 290050003 | I14: 29005000377012 | J14: Samjhana Tamang | K14: ;Demgf tfdfË | L14: F | M14: =IF(L14="M","k'?if","dlxnf") -> dlxnf | N14: J | O14: Tamang | P14: tfdfË | Q14: Nepali | R14: 13 | S14: 9845353754 | T14: 2042-8-3 | U14: 1308/2043 | V14: Teacher | W14: Intermediate | Y14: Lower Basic | Z14: 3rd | AA14: Rahat | AB14: /fxt
A15: Bagmati Province | B15: Rasuwa | D15: Gosaikunda Gaunpalika | F15: Saraswati Adharbhut Vidyalaya | H15: 290050003 | I15: 29005000377011 | J15: Karma Chhenjom Tamanag | K15: s/df r]Ghf]Ë | L15: F | M15: =IF(L15="M","k'?if","dlxnf") -> dlxnf | N15: J | O15: Tamang | P15: tfdfË | Q15: Nepali | R15: 14 | S15: 9849822343 | T15: 2039-4-8 | U15: 134/59 | V15: Teacher | W15: Intermediate | Y15: Lower Basic | Z15: 3rd | AA15: Rahat | AB15: /fxt
A16: Bagmati Province | B16: Rasuwa | D16: Gosaikunda Gaunpalika | F16: Saraswati Adharbhut Vidyalaya | H16: 290050003 | I16: 29005000377009 | J16: Goma Adhikari | K16: uf]df clwsf/L | L16: F | M16: =IF(L16="M","k'?if","dlxnf") -> dlxnf | N16: B/C | O16: Nepali | P16: g]kfnL | Q16: Nepali | R16: 15 | S16: 9849418723 | T16: 2046-4-19 | U16: 253015 | V16: Teacher | W16: Masters | X16: Edu | Y16: Lower Basic | Z16: 3rd | AA16: Permanent | AB16: :yfoL
A17: Bagmati Province | B17: Rasuwa | D17: Gosaikunda Gaunpalika | F17: Saraswati Adharbhut Vidyalaya | H17: 290050003 | I17: 29005000377005 | J17: Karpo Tamang | K17: s/kf] tfdfË | L17: M | M17: =IF(L17="M","k'?if","dlxnf") -> k'?if | N17: J | O17: Tamang | P17: tfdfË | Q17: Nepali | R17: 16 | S17: 9860600117 | T17: 2046-9-4 | U17: 5910/4 | V17: Teacher | W17: Intermediate | Y17: Lower Basic | Z17: 3rd | AA17: Rahat | AB17: /fxt
A18: Bagmati Province | B18: Rasuwa | D18: Gosaikunda Gaunpalika | F18: Saraswati Adharbhut Vidyalaya | H18: 290050003 | I18: 29005000377007 | J18: Tina Tamang | K18: tLgf tfdfË | L18: F | M18: =IF(L18="M","k'?if","dlxnf") -> dlxnf | N18: J | O18: Tamang | P18: tfdfË | Q18: Nepali | R18: 17 | S18: 9869180412 | T18: 2055-10-5 | U18: 23-01-73-00471 | V18: Teacher | W18: Under SLC | Y18: ECD/PPC | Z18: 3rd | AA18: ECD Facilitator | AB18: O;L8L ;xof]uL
A19: Bagmati Province | B19: Rasuwa | D19: Gosaikunda Gaunpalika | F19: Saraswati Adharbhut Vidyalaya | H19: 290050003 | I19: 29005000377004 | J19: Lanam Ghale | K19: ngd 3n] | L19: M | M19: =IF(L19="M","k'?if","dlxnf") -> k'?if | N19: J | O19: Tamang | P19: tfdfË | Q19: Nepali | R19: 18 | S19: 9741086460 | T19: 2037-7-20 | U19: Ka 479 | V19: Head Teacher | W19: Intermediate | X19: Education | Y19: Lower Basic | Z19: 3rd | AA19: Permanent | AB19: :yfoL
A20: Bagmati Province | B20: Rasuwa | D20: Gosaikunda Gaunpalika | F20: Saraswati Adharbhut Vidyalaya | H20: 290050003 | I20: 29005000377008 | J20: Ram Krisna Thapa Magar | K20: /fds[i0f yfkfdu/ | L20: M | M20: =IF(L20="M","k'?if","dlxnf") -> k'?if | N20: J | O20: Nepali | P20: g]kfnL | Q20: Nepali | R20: 19 | S20: 9841087987 | T20: 2043-10-11 | U20: 88680 | V20: Teacher | W20: Masters | X20: Edu | Y20: Lower Basic | Z20: 3rd | AA20: Permanent | AB20: :yfoL
A21: Bagmati Province | B21: Rasuwa | D21: Gosaikunda Gaunpalika | F21: Rasuwa Ma V | H21: 290050006 | I21: 29005000677042 | J21: Chandra Shekhar Kasula | K21: rGb| z]v/ sf}znf | L21: M | M21: =IF(L21="M","k'?if","dlxnf") -> k'?if | N21: J | O21: Newari | P21: g]jf/L | Q21: Nepali | R21: 20 | S21: 9840058885 | T21: 2047-5-14 | U21: 293012/206 | V21: Teacher | W21: MPhil | X21: Education | Y21: Secondary | Z21: 3rd | AA21: Permanent | AB21: :yfoL
A22: Bagmati Province | B22: Rasuwa | D22: Gosaikunda Gaunpalika | F22: Rasuwa Ma V | H22: 290050006 | I22: 29005000677042 | J22: Chandra Shekhar Kasula | K22: rGb| z]v/ sf}znf | L22: M | M22: =IF(L22="M","k'?if","dlxnf") -> k'?if | N22: J | O22: Newari | P22: g]jf/L | Q22: Nepali | R22: 21 | S22: 9840058885 | T22: 2047-5-14 | U22: 293012/206 | V22: Teacher | W22: MPhil | X22: Education | Y22: Secondary | Z22: 3rd | AA22: Permanent | AB22: :yfoL
A23: Bagmati Province | B23: Rasuwa | D23: Gosaikunda Gaunpalika | F23: Rasuwa Ma V | H23: 290050006 | I23: 29005000677049 | J23: Narendra Bahadur Badaila | K23: g/]Gb| axfb'/ ab}nf | L23: M | M23: =IF(L23="M","k'?if","dlxnf") -> k'?if | N23: B/C | O23: Nepali | P23: g]kfnL | Q23: Nepali | R23: 22 | T23: 2044-10-28 | U23: 2/22482/439 | V23: Teacher | W23: MPhil | X23: English | Y23: Secondary | Z23: 3rd | AA23: Temporary | AB23: c:yfoL
A24: Bagmati Province | B24: Rasuwa | D24: Gosaikunda Gaunpalika | F24: Rasuwa Ma V | H24: 290050006 | I24: 29005000677049 | J24: Narendra Bahadur Badaila | L24: M | M24: =IF(L24="M","k'?if","dlxnf") -> k'?if | N24: B/C | O24: Nepali | P24: g]kfnL | Q24: Nepali | R24: 23 | T24: 2044-10-28 | U24: 2/22482/439 | V24: Teacher | W24: MPhil | X24: English | Y24: Secondary | Z24: 3rd | AA24: Temporary | AB24: c:yfoL
A25: Bagmati Province | B25: Rasuwa | D25: Gosaikunda Gaunpalika | F25: Rasuwa Ma V | H25: 290050006 | I25: 29005000677049 | J25: Narendra Bahadur Badaila | L25: M | M25: =IF(L25="M","k'?if","dlxnf") -> k'?if | N25: B/C | O25: Nepali | P25: g]kfnL | Q25: Nepali | R25: 24 | T25: 2044-10-28 | U25: 2/22482/439 | V25: Teacher | W25: MPhil | X25: English | Y25: Secondary | Z25: 3rd | AA25: Temporary | AB25: c:yfoL
A26: Bagmati Province | B26: Rasuwa | D26: Gosaikunda Gaunpalika | F26: Rasuwa Ma V | H26: 290050006 | I26: 29005000677049 | J26: Narendra Bahadur Badaila | L26: M | M26: =IF(L26="M","k'?if","dlxnf") -> k'?if | N26: B/C | O26: Nepali | P26: g]kfnL | Q26: Nepali | R26: 25 | T26: 2044-10-28 | U26: 2/22482/439 | V26: Teacher | W26: MPhil | X26: English | Y26: Secondary | Z26: 3rd | AA26: Temporary | AB26: c:yfoL
A27: Bagmati Province | B27: Rasuwa | D27: Gosaikunda Gaunpalika | F27: Rasuwa Ma V | H27: 290050006 | I27: 29005000677048 | J27: Suraj Gurung | K27: ;'/h u'?Ë | L27: M | M27: =IF(L27="M","k'?if","dlxnf") -> k'?if | N27: J | O27: Nepali | P27: g]kfnL | Q27: Nepali | R27: 26 | S27: 9863554567 | T27: 2041-7-27 | U27: 69498 | V27: Teacher | W27: Masters | X27: English | Y27: Upper Basic | Z27: 3rd | AA27: Permanent | AB27: :yfoL
A28: Bagmati Province | B28: Rasuwa | D28: Gosaikunda Gaunpalika | F28: Rasuwa Ma V | H28: 290050006 | I28: 29005000677048 | J28: Suraj Gurung | L28: M | M28: =IF(L28="M","k'?if","dlxnf") -> k'?if | N28: J | O28: Nepali | P28: g]kfnL | Q28: Nepali | R28: 27 | S28: 9863554567 | T28: 2041-7-27 | U28: 69498 | V28: Teacher | W28: Masters | X28: English | Y28: Upper Basic | Z28: 3rd | AA28: Permanent | AB28: :yfoL
A29: Bagmati Province | B29: Rasuwa | D29: Gosaikunda Gaunpalika | F29: Rasuwa Ma V | H29: 290050006 | I29: 29005000677047 | J29: Prem Rai | K29: k|]d /fO} | L29: M | M29: =IF(L29="M","k'?if","dlxnf") -> k'?if | N29: J | Q29: Nepali | R29: 28 | T29: 2035-6-3 | U29: 51236/53236 | V29: Teacher | W29: Bachelors | X29: Nepali | Y29: Lower Basic | Z29: 3rd | AA29: Permanent | AB29: :yfoL
A30: Bagmati Province | B30: Rasuwa | D30: Gosaikunda Gaunpalika | F30: Rasuwa Ma V | H30: 290050006 | I30: 29005000677046 | J30: Baikuntha Khatiwada | K30: a}s'G7 vltj8f | L30: M | M30: =IF(L30="M","k'?if","dlxnf") -> k'?if | N30: B/C | Q30: Nepali | R30: 29 | S30: 9849076864 | T30: 2049-5-5 | U30: 261/39912 | V30: Teacher | W30: MPhil | X30: English | Y30: Lower Basic | Z30: 3rd | AA30: Permanent | AB30: :yfoL
A31: Bagmati Province | B31: Rasuwa | D31: Gosaikunda Gaunpalika | F31: Rasuwa Ma V | H31: 290050006 | I31: 29005000677045 | J31: Menuka Tiwari | K31: d]g'sf ltjf/L | L31: F | M31: =IF(L31="M","k'?if","dlxnf") -> dlxnf | N31: B/C | O31: Nepali | P31: g]kfnL | Q31: Nepali | R31: 30 | S31: 9843785568 | T31: 2043-10-6 | U31: 12165 | V31: Teacher | W31: Masters | X31: Nepali | Y31: Lower Basic | Z31: 3rd | AA31: Permanent | AB31: :yfoL
A32: Bagmati Province | B32: Rasuwa | D32: Gosaikunda Gaunpalika | F32: Rasuwa Ma V | H32: 290050006 | I32: 29005000677045 | J32: Menuka Tiwari | L32: F | M32: =IF(L32="M","k'?if","dlxnf") -> dlxnf | N32: B/C | O32: Nepali | P32: g]kfnL | Q32: Nepali | R32: 31 | S32: 9843785568 | T32: 2043-10-6 | U32: 12165 | V32: Teacher | W32: Masters | X32: Nepali | Y32: Lower Basic | Z32: 3rd | AA32: Permanent | AB32: :yfoL
A33: Bagmati Province | B33: Rasuwa | D33: Gosaikunda Gaunpalika | F33: Rasuwa Ma V | H33: 290050006 | I33: 29005000677040 | J33: Suraj Bi Ka | K33: ;'/h las | L33: M | M33: =IF(L33="M","k'?if","dlxnf") -> k'?if | N33: D | O33: Nepali | P33: g]kfnL | Q33: Nepali | R33: 32 | S33: 9840261906 | T33: 2046-2-20 | U33: 303056/238 | V33: Teacher | W33: Masters | X33: Education | Y33: Secondary | Z33: 3rd | AA33: Permanent | AB33: :yfoL
A34: Bagmati Province | B34: Rasuwa | D34: Gosaikunda Gaunpalika | F34: Rasuwa Ma V | H34: 290050006 | I34: 29005000677040 | J34: Suraj Bi Ka | L34: M | M34: =IF(L34="M","k'?if","dlxnf") -> k'?if | N34: D | O34: Nepali | P34: g]kfnL | Q34: Nepali | R34: 33 | S34: 9840261906 | T34: 2046-2-20 | U34: 303056/238 | V34: Teacher | W34: Masters | X34: Education | Y34: Secondary | Z34: 3rd | AA34: Permanent | AB34: :yfoL
A35: Bagmati Province | B35: Rasuwa | D35: Gosaikunda Gaunpalika | F35: Rasuwa Ma V | H35: 290050006 | I35: 29005000677036 | J35: Padam Raj Bhatt | K35: kbd/fh eQ | L35: M | M35: =IF(L35="M","k'?if","dlxnf") -> k'?if | N35: B/C | O35: Nepali | P35: g]kfnL | Q35: Nepali | R35: 34 | S35: 9848780078 | T35: 2045-3-15 | U35: 29713 | V35: Teacher | W35: MPhil | X35: Education | Y35: Secondary | Z35: 2nd | AA35: Temporary | AB35: c:yfoL
A36: Bagmati Province | B36: Rasuwa | D36: Gosaikunda Gaunpalika | F36: Rasuwa Ma V | H36: 290050006 | I36: 29005000677036 | J36: Padam Raj Bhatt | L36: M | M36: =IF(L36="M","k'?if","dlxnf") -> k'?if | N36: B/C | O36: Nepali | P36: g]kfnL | Q36: Nepali | R36: 35 | S36: 9848780078 | T36: 2045-3-15 | U36: 29713 | V36: Teacher | W36: MPhil | X36: Education | Y36: Secondary | Z36: 2nd | AA36: Temporary | AB36: c:yfoL
A37: Bagmati Province | B37: Rasuwa | D37: Gosaikunda Gaunpalika | F37: Rasuwa Ma V | H37: 290050006 | I37: 29005000677035 | J37: Parbati Khanal | K37: kfj{tL vgfn | L37: F | M37: =IF(L37="M","k'?if","dlxnf") -> dlxnf | N37: B/C | O37: Nepali | P37: g]kfnL | Q37: Nepali | R37: 36 | S37: 9841889031 | T37: 2035-5-26 | U37: 19948 | V37: Teacher | W37: MPhil | X37: Education | Y37: Secondary | Z37: 3rd | AA37: Temporary | AB37: c:yfoL
A38: Bagmati Province | B38: Rasuwa | D38: Gosaikunda Gaunpalika | F38: Rasuwa Ma V | H38: 290050006 | I38: 29005000677034 | J38: Saraswati Thapa | K38: ;/:jtL yfkf | L38: F | M38: =IF(L38="M","k'?if","dlxnf") -> dlxnf | N38: O | O38: Nepali | P38: g]kfnL | Q38: Nepali | R38: 37 | T38: 2051-4-27 | U38: 101001/2463 | V38: Teacher | W38: Bachelors | X38: Education | Y38: ECD/PPC | Z38: 3rd | AA38: ECD Facilitator | AB38: O;L8L ;xof]uL
A39: Bagmati Province | B39: Rasuwa | D39: Gosaikunda Gaunpalika | F39: Rasuwa Ma V | H39: 290050006 | I39: 29005000677034 | J39: Saraswati Thapa | L39: F | M39: =IF(L39="M","k'?if","dlxnf") -> dlxnf | N39: O | O39: Nepali | P39: g]kfnL | Q39: Nepali | R39: 38 | T39: 2051-4-27 | U39: 101001/2463 | V39: Teacher | W39: Bachelors | X39: Education | Y39: ECD/PPC | Z39: 3rd | AA39: ECD Facilitator | AB39: O;L8L ;xof]uL
A40: Bagmati Province | B40: Rasuwa | D40: Gosaikunda Gaunpalika | F40: Rasuwa Ma V | H40: 290050006 | I40: 29005000677032 | J40: Tilak Ghising | K40: l6ns l3l;Ë | L40: M | M40: =IF(L40="M","k'?if","dlxnf") -> k'?if | N40: J | O40: Tamang | P40: tfdfË | Q40: Nepali | R40: 39 | S40: 9841018139 | T40: 2039-3-28 | U40: 200 | V40: Teacher | W40: MPhil | X40: Management | Y40: Higher Secondary | Z40: 3rd | AA40: Temporary | AB40: c:yfoL
...

Sheet list
A1: Province | B1: District | D1: Local Level | F1: School | H1: 290140001 | I1: 29014000177010 | J1: Ambika Karki | K1: clDasf sfsL{ | L1: F | M1: =IF(L1="M","k'?if","dlxnf") -> dlxnf | N1: O | O1: Nepali | P1: g]kfnL | Q1: Nepali | R1: 83 | S1: 9741086452 | T1: 2035-3-18 | U1: 66480127 | V1: Teacher | W1: Masters | X1: Sociology | Y1: Higher Secondary | Z1: 2nd | AA1: Temporary | AB1: c:yfoL
A2: Bagmati Province | B2: Rasuwa | D2: Gosaikunda Gaunpalika | F2: Pra V Khamging | H2: 290020002 | I2: 29002000277002 | J2: Temba Tamang | K2: t]Daf tfdfË | L2: M | M2: =IF(L2="M","k'?if","dlxnf") -> k'?if | N2: J | O2: Sherpa | P2: z]kf{ | Q2: Nepali | R2: 1 | S2: 9741016525 | T2: 2035-10-15 | U2: 4740-107 | V2: Teacher | W2: Intermediate | Y2: Lower Basic | Z2: 3rd | AA2: Permanent | AB2: :yfoL
A3: Bagmati Province | B3: Rasuwa | D3: Gosaikunda Gaunpalika | F3: Pra V Khamging | H3: 290020002 | I3: 29002000277003 | J3: Maya Sherpa | K3: dfof z]kf{ | L3: F | M3: =IF(L3="M","k'?if","dlxnf") -> dlxnf | N3: J | O3: Tamang | P3: tfdfË | Q3: Nepali | R3: 2 | S3: 9808712730 | T3: 2034-10-1 | U3: 3781 | V3: Teacher | W3: Bachelors | X3: Education | Y3: Lower Basic | Z3: 3rd | AA3: Permanent | AB3: :yfoL
A4: Bagmati Province | B4: Rasuwa | D4: Gosaikunda Gaunpalika | F4: Pra V Khamging | H4: 290020002 | I4: 29002000277001 | J4: Kabita Neupane | K4: slatf Gof}kfg] | L4: F | M4: =IF(L4="M","k'?if","dlxnf") -> dlxnf | N4: O | O4: Nepali | P4: g]kfnL | Q4: Nepali | R4: 3 | S4: 9741161789 | T4: 2042-1-18 | U4: 306 | V4: Teacher | W4: Masters | X4: Education | Y4: Lower Basic | Z4: 3rd | AA4: Temporary | AB4: c:yfoL
A5: Bagmati Province | B5: Rasuwa | D5: Gosaikunda Gaunpalika | F5: Lingling Pra V | H5: 290020003 | I5: 29002000377002 | J5: Nirmal Jang Sherpa | K5: lgd{n h+u z]kf{ | L5: M | M5: =IF(L5="M","k'?if","dlxnf") -> k'?if | N5: J | O5: Tamang | P5: tfdfË | Q5: Nepali | R5: 4 | S5: 9860228865 | T5: 2031-11-1 | U5: 3384 | V5: Teacher | W5: Masters | Y5: Lower Basic | Z5: 3rd | AA5: Permanent | AB5: :yfoL
A6: Bagmati Province | B6: Rasuwa | D6: Gosaikunda Gaunpalika | F6: Bhimali Pra V | H6: 290020003 | I6: 29002000377001 | J6: Sushil Koirala | K6: ;'lzn sf]O/fnf | L6: M | M6: =IF(L6="M","k'?if","dlxnf") -> k'?if | N6: O | O6: Nepali | P6: g]kfnL | Q6: Nepali | R6: 5 | S6: 9741035103 | T6: 2025-7-3 | U6: 700 | V6: Head Teacher | W6: Bachelors | X6: Education | Y6: Lower Basic | Z6: 3rd | AA6: Permanent | AB6: :yfoL
A7: Bagmati Province | B7: Rasuwa | D7: Gosaikunda Gaunpalika | F7: Bhimali Pra V | H7: 290050001 | I7: 29005000177001 | J7: Tulshingi Tamang | K7: t'lN;+uL tfdfË | L7: M | M7: =IF(L7="M","k'?if","dlxnf") -> k'?if | N7: J | O7: Tamang | P7: tfdfË | Q7: Nepali | R7: 6 | T7: 2027-1-15 | U7: 270-702 | V7: Head Teacher | W7: Intermediate | Y7: Lower Basic | Z7: 3rd | AA7: Permanent | AB7: :yfoL
A8: Bagmati Province | B8: Rasuwa | D8: Gosaikunda Gaunpalika | F8: Bhimali Pra V | H8: 290050001 | I8: 29005000177005 | J8: Yuna Thokra | K8: o'gf yf]s/f | L8: F | M8: =IF(L8="M","k'?if","dlxnf") -> dlxnf | N8: J | O8: Nepali | P8: tfdfË | Q8: Nepali | R8: 7 | T8: 2052-5-17 | U8: 155 | V8: Teacher | Y8: ECD/PPC | Z8: 3rd | AA8: ECD Facilitator | AB8: O;L8L ;xof]uL
A9: Bagmati Province | B9: Rasuwa | D9: Gosaikunda Gaunpalika | F9: Saraswati Adharbhut Vidyalaya | H9: 290050001 | I9: 29005000177006 | J9: Urmila Lama | K9: pld{nf nfdf | L9: F | M9: =IF(L9="M","k'?if","dlxnf") -> dlxnf | N9: J | O9: Tamang | P9: tfdfË | Q9: Nepali | R9: 8 | S9: 9843404440 | T9: 2033-8-3 | U9: 3769 | V9: Teacher | W9: Intermediate | X9: Edu | Y9: Lower Basic | Z9: 3rd | AA9: Permanent | AB9: :yfoL
A10: Bagmati Province | B10: Rasuwa | D10: Gosaikunda Gaunpalika | F10: Saraswati Adharbhut Vidyalaya | H10: 290050002 | I10: 29005000277007 | J10: Krishna Bahadur Kumal | K10: s[i0f axfb'/ s'dfn | L10: M | M10: =IF(L10="M","k'?if","dlxnf") -> k'?if | N10: J | O10: Nepali | P10: g]kfnL | Q10: Nepali | R10: 10 | T10: 2023-11-23 | U10: 424 | V10: Head Teacher | W10: SLC | Y10: Lower Basic | Z10: 3rd | AA10: Permanent | AB10: :yfoL
A11: Bagmati Province | B11: Rasuwa | D11: Gosaikunda Gaunpalika | F11: Saraswati Adharbhut Vidyalaya | H11: 290050002 | I11: 29005000277006 | J11: Yuna Tamang | K11: o'gf tfdfË | L11: F | M11: =IF(L11="M","k'?if","dlxnf") -> dlxnf | N11: J | O11: Tamang | P11: tfdfË | Q11: Nepali | R11: 11 | S11: 9823756146 | T11: 2054-10-17 | U11: 23/10/72/01088 | V11: Teacher | Y11: ECD/PPC | Z11: 3rd | AA11: ECD Facilitator | AB11: O;L8L ;xof]uL
A12: Bagmati Province | B12: Rasuwa | D12: Gosaikunda Gaunpalika | F12: Saraswati Adharbhut Vidyalaya | H12: 290050003 | I12: 29005000377010 | J12: Durga Bhatta | K12: b\uf{ eQ | L12: F | M12: =IF(L12="M","k'?if","dlxnf") -> dlxnf | N12: B/C | O12: Nepali | P12: g]kfnL | Q12: Nepali | R12: 12 | T12: 2046-11-27 | U12: 113572 | V12: Teacher | W12: Bachelors | Y12: Lower Basic | Z12: 3rd | AA12: Permanent | AB12: :yfoL
A13: Bagmati Province | B13: Rasuwa | D13: Gosaikunda Gaunpalika | F13: Saraswati Adharbhut Vidyalaya | H13: 290050003 | I13: 29005000377012 | J13: Samjhana Tamang | K13: ;Demgf tfdfË | L13: F | M13: =IF(L13="M","k'?if","dlxnf") -> dlxnf | N13: J | O13: Tamang | P13: tfdfË | Q13: Nepali | R13: 13 | S13: 9845353754 | T13: 2042-8-3 | U13: 1308/2043 | V13: Teacher | W13: Intermediate | Y13: Lower Basic | Z13: 3rd | AA13: Rahat | AB13: /fxt
A14: Bagmati Province | B14: Rasuwa | D14: Gosaikunda Gaunpalika | F14: Saraswati Adharbhut Vidyalaya | H14: 290050003 | I14: 29005000377011 | J14: Karma Chhenjom Tamanag | K14: s/df r]Ghf]Ë | L14: F | M14: =IF(L14="M","k'?if","dlxnf") -> dlxnf | N14: J | O14: Tamang | P14: tfdfË | Q14: Nepali | R14: 14 | S14: 9849822343 | T14: 2039-4-8 | U14: 134/59 | V14: Teacher | W14: Intermediate | Y14: Lower Basic | Z14: 3rd | AA14: Rahat | AB14: /fxt
A15: Bagmati Province | B15: Rasuwa | D15: Gosaikunda Gaunpalika | F15: Saraswati Adharbhut Vidyalaya | H15: 290050003 | I15: 29005000377009 | J15: Goma Adhikari | K15: uf]df clwsf/L | L15: F | M15: =IF(L15="M","k'?if","dlxnf") -> dlxnf | N15: B/C | O15: Nepali | P15: g]kfnL | Q15: Nepali | R15: 15 | S15: 9849418723 | T15: 2046-4-19 | U15: 253015 | V15: Teacher | W15: Masters | X15: Edu | Y15: Lower Basic | Z15: 3rd | AA15: Permanent | AB15: :yfoL
A16: Bagmati Province | B16: Rasuwa | D16: Gosaikunda Gaunpalika | F16: Saraswati Adharbhut Vidyalaya | H16: 290050003 | I16: 29005000377005 | J16: Karpo Tamang | K16: s/kf] tfdfË | L16: M | M16: =IF(L16="M","k'?if","dlxnf") -> k'?if | N16: J | O16: Tamang | P16: tfdfË | Q16: Nepali | R16: 16 | S16: 9860600117 | T16: 2046-9-4 | U16: 5910/4 | V16: Teacher | W16: Intermediate | Y16: Lower Basic | Z16: 3rd | AA16: Rahat | AB16: /fxt
A17: Bagmati Province | B17: Rasuwa | D17: Gosaikunda Gaunpalika | F17: Rasuwa Ma V | H17: 290050003 | I17: 29005000377007 | J17: Tina Tamang | K17: tLgf tfdfË | L17: F | M17: =IF(L17="M","k'?if","dlxnf") -> dlxnf | N17: J | O17: Tamang | P17: tfdfË | Q17: Nepali | R17: 17 | S17: 9869180412 | T17: 2055-10-5 | U17: 23-01-73-00471 | V17: Teacher | W17: Under SLC | Y17: ECD/PPC | Z17: 3rd | AA17: ECD Facilitator | AB17: O;L8L ;xof]uL
A18: Bagmati Province | B18: Rasuwa | D18: Gosaikunda Gaunpalika | F18: Rasuwa Ma V | H18: 290050003 | I18: 29005000377004 | J18: Lanam Ghale | K18: ngd 3n] | L18: M | M18: =IF(L18="M","k'?if","dlxnf") -> k'?if | N18: J | O18: Tamang | P18: tfdfË | Q18: Nepali | R18: 18 | S18: 9741086460 | T18: 2037-7-20 | U18: Ka 479 | V18: Head Teacher | W18: Intermediate | X18: Education | Y18: Lower Basic | Z18: 3rd | AA18: Permanent | AB18: :yfoL
A19: Bagmati Province | B19: Rasuwa | D19: Gosaikunda Gaunpalika | F19: Rasuwa Ma V | H19: 290050003 | I19: 29005000377008 | J19: Ram Krisna Thapa Magar | K19: /fds[i0f yfkfdu/ | L19: M | M19: =IF(L19="M","k'?if","dlxnf") -> k'?if | N19: J | O19: Nepali | P19: g]kfnL | Q19: Nepali | R19: 19 | S19: 9841087987 | T19: 2043-10-11 | U19: 88680 | V19: Teacher | W19: Masters | X19: Edu | Y19: Lower Basic | Z19: 3rd | AA19: Permanent | AB19: :yfoL
A20: Bagmati Province | B20: Rasuwa | D20: Gosaikunda Gaunpalika | F20: Rasuwa Ma V | H20: 290050006 | I20: 29005000677042 | J20: Chandra Shekhar Kasula | K20: rGb| z]v/ sf}znf | L20: M | M20: =IF(L20="M","k'?if","dlxnf") -> k'?if | N20: J | O20: Newari | P20: g]jf/L | Q20: Nepali | R20: 20 | S20: 9840058885 | T20: 2047-5-14 | U20: 293012/206 | V20: Teacher | W20: MPhil | X20: Education | Y20: Secondary | Z20: 3rd | AA20: Permanent | AB20: :yfoL
A21: Bagmati Province | B21: Rasuwa | D21: Gosaikunda Gaunpalika | F21: Rasuwa Ma V | H21: 290050006 | I21: 29005000677049 | J21: Narendra Bahadur Badaila | K21: g/]Gb| axfb'/ ab}nf | L21: M | M21: =IF(L21="M","k'?if","dlxnf") -> k'?if | N21: B/C | O21: Nepali | P21: g]kfnL | Q21: Nepali | R21: 22 | T21: 2044-10-28 | U21: 2/22482/439 | V21: Teacher | W21: MPhil | X21: English | Y21: Secondary | Z21: 3rd | AA21: Temporary | AB21: c:yfoL
A22: Bagmati Province | B22: Rasuwa | D22: Gosaikunda Gaunpalika | F22: Rasuwa Ma V | H22: 290050006 | I22: 29005000677048 | J22: Suraj Gurung | K22: ;'/h u'?Ë | L22: M | M22: =IF(L22="M","k'?if","dlxnf") -> k'?if | N22: J | O22: Nepali | P22: g]kfnL | Q22: Nepali | R22: 26 | S22: 9863554567 | T22: 2041-7-27 | U22: 69498 | V22: Teacher | W22: Masters | X22: English | Y22: Upper Basic | Z22: 3rd | AA22: Permanent | AB22: :yfoL
A23: Bagmati Province | B23: Rasuwa | D23: Gosaikunda Gaunpalika | F23: Rasuwa Ma V | H23: 290050006 | I23: 29005000677047 | J23: Prem Rai | K23: k|]d /fO} | L23: M | M23: =IF(L23="M","k'?if","dlxnf") -> k'?if | N23: J | Q23: Nepali | R23: 28 | T23: 2035-6-3 | U23: 51236/53236 | V23: Teacher | W23: Bachelors | X23: Nepali | Y23: Lower Basic | Z23: 3rd | AA23: Permanent | AB23: :yfoL
A24: Bagmati Province | B24: Rasuwa | D24: Gosaikunda Gaunpalika | F24: Rasuwa Ma V | H24: 290050006 | I24: 29005000677046 | J24: Baikuntha Khatiwada | K24: a}s'G7 vltj8f | L24: M | M24: =IF(L24="M","k'?if","dlxnf") -> k'?if | N24: B/C | Q24: Nepali | R24: 29 | S24: 9849076864 | T24: 2049-5-5 | U24: 261/39912 | V24: Teacher | W24: MPhil | X24: English | Y24: Lower Basic | Z24: 3rd | AA24: Permanent | AB24: :yfoL
A25: Bagmati Province | B25: Rasuwa | D25: Gosaikunda Gaunpalika | F25: Rasuwa Ma V | H25: 290050006 | I25: 29005000677045 | J25: Menuka Tiwari | K25: d]g'sf ltjf/L | L25: F | M25: =IF(L25="M","k'?if","dlxnf") -> dlxnf | N25: B/C | O25: Nepali | P25: g]kfnL | Q25: Nepali | R25: 30 | S25: 9843785568 | T25: 2043-10-6 | U25: 12165 | V25: Teacher | W25: Masters | X25: Nepali | Y25: Lower Basic | Z25: 3rd | AA25: Permanent | AB25: :yfoL
A26: Bagmati Province | B26: Rasuwa | D26: Gosaikunda Gaunpalika | F26: Rasuwa Ma V | H26: 290050006 | I26: 29005000677040 | J26: Suraj Bi Ka | K26: ;'/h las | L26: M | M26: =IF(L26="M","k'?if","dlxnf") -> k'?if | N26: D | O26: Nepali | P26: g]kfnL | Q26: Nepali | R26: 32 | S26: 9840261906 | T26: 2046-2-20 | U26: 303056/238 | V26: Teacher | W26: Masters | X26: Education | Y26: Secondary | Z26: 3rd | AA26: Permanent | AB26: :yfoL
A27: Bagmati Province | B27: Rasuwa | D27: Gosaikunda Gaunpalika | F27: Rasuwa Ma V | H27: 290050006 | I27: 29005000677036 | J27: Padam Raj Bhatt | K27: kbd/fh eQ | L27: M | M27: =IF(L27="M","k'?if","dlxnf") -> k'?if | N27: B/C | O27: Nepali | P27: g]kfnL | Q27: Nepali | R27: 34 | S27: 9848780078 | T27: 2045-3-15 | U27: 29713 | V27: Teacher | W27: MPhil | X27: Education | Y27: Secondary | Z27: 2nd | AA27: Temporary | AB27: c:yfoL
A28: Bagmati Province | B28: Rasuwa | D28: Gosaikunda Gaunpalika | F28: Rasuwa Ma V | H28: 290050006 | I28: 29005000677035 | J28: Parbati Khanal | K28: kfj{tL vgfn | L28: F | M28: =IF(L28="M","k'?if","dlxnf") -> dlxnf | N28: B/C | O28: Nepali | P28: g]kfnL | Q28: Nepali | R28: 36 | S28: 9841889031 | T28: 2035-5-26 | U28: 19948 | V28: Teacher | W28: MPhil | X28: Education | Y28: Secondary | Z28: 3rd | AA28: Temporary | AB28: c:yfoL
A29: Bagmati Province | B29: Rasuwa | D29: Gosaikunda Gaunpalika | F29: Rasuwa Ma V | H29: 290050006 | I29: 29005000677034 | J29: Saraswati Thapa | K29: ;/:jtL yfkf | L29: F | M29: =IF(L29="M","k'?if","dlxnf") -> dlxnf | N29: O | O29: Nepali | P29: g]kfnL | Q29: Nepali | R29: 37 | T29: 2051-4-27 | U29: 101001/2463 | V29: Teacher | W29: Bachelors | X29: Education | Y29: ECD/PPC | Z29: 3rd | AA29: ECD Facilitator | AB29: O;L8L ;xof]uL
A30: Bagmati Province | B30: Rasuwa | D30: Gosaikunda Gaunpalika | F30: Rasuwa Ma V | H30: 290050006 | I30: 29005000677032 | J30: Tilak Ghising | K30: l6ns l3l;Ë | L30: M | M30: =IF(L30="M","k'?if","dlxnf") -> k'?if | N30: J | O30: Tamang | P30: tfdfË | Q30: Nepali | R30: 39 | S30: 9841018139 | T30: 2039-3-28 | U30: 200 | V30: Teacher | W30: MPhil | X30: Management | Y30: Higher Secondary | Z30: 3rd | AA30: Temporary | AB30: c:yfoL
A31: Bagmati Province | B31: Rasuwa | D31: Gosaikunda Gaunpalika | F31: Rasuwa Ma V | H31: 290050006 | I31: 29005000677030 | J31: Sujata Ghale | K31: ;'hftf 3n] | L31: F | M31: =IF(L31="M","k'?if","dlxnf") -> dlxnf | N31: J | O31: Tamang | P31: tfdfË | Q31: Nepali | R31: 41 | S31: 9741086524 | T31: 2046-10-15 | U31: 6473/2894 | V31: Teacher | W31: Masters | X31: Education | Y31: Upper Basic | Z31: 3rd | AA31: Permanent | AB31: :yfoL
A32: Bagmati Province | B32: Rasuwa | D32: Gosaikunda Gaunpalika | F32: Rasuwa Ma V | H32: 290050006 | I32: 29005000677028 | J32: Kippa Chhiring Tamang | K32: lskf l5l/Ë tfdfË | L32: M | M32: =IF(L32="M","k'?if","dlxnf") -> k'?if | N32: J | O32: Tamang | P32: tfdfË | Q32: Nepali | R32: 42 | S32: 9741014084 | T32: 2021-10-1 | U32: 51/262 | V32: Teacher | W32: Intermediate | Y32: Lower Basic | Z32: 2nd | AA32: Permanent | AB32: :yfoL
A33: Bagmati Province | B33: Rasuwa | D33: Gosaikunda Gaunpalika | F33: Rasuwa Ma V | H33: 290050006 | I33: 29005000677021 | J33: Tempa Risang Ghale | K33: t]Dkf l/;fË 3n] | L33: M | M33: =IF(L33="M","k'?if","dlxnf") -> k'?if | N33: J | O33: Tamang | P33: tfdfË | Q33: Nepali | R33: 44 | S33: 9843110463 | T33: 2026-4-5 | U33: 1267/609 | V33: Head Teacher | W33: Masters | X33: Education | Y33: Upper Basic | Z33: 2nd | AA33: Permanent | AB33: :yfoL
A34: Bagmati Province | B34: Rasuwa | D34: Gosaikunda Gaunpalika | F34: Rasuwa Ma V | H34: 290050006 | I34: 29005000677002 | J34: Chij Kumar Ghale | K34: lrh s'df/ 3n] | L34: M | M34: =IF(L34="M","k'?if","dlxnf") -> k'?if | N34: J | O34: Tamang | P34: tfdfË | Q34: Nepali | R34: 46 | S34: 9841888699 | T34: 2026-3-4 | U34: 435 | V34: Teacher | W34: Bachelors | X34: Education | Y34: Lower Basic | Z34: 2nd | AA34: Permanent | AB34: :yfoL
A35: Bagmati Province | B35: Rasuwa | D35: Gosaikunda Gaunpalika | F35: Rasuwa Ma V | H35: 290050006 | I35: 29005000677044 | J35: Laxmi Tiwari | K35: nlId ltjf/L | L35: F | M35: =IF(L35="M","k'?if","dlxnf") -> dlxnf | N35: B/C | O35: Nepali | P35: g]kfnL | Q35: Nepali | R35: 47 | S35: 9849434110 | T35: 2045-8-7 | U35: 6859/3119 | V35: Teacher | W35: MPhil | Y35: Lower Basic | Z35: 3rd | AA35: Permanent | AB35: :yfoL
A36: Bagmati Province | B36: Rasuwa | D36: Gosaikunda Gaunpalika | F36: Rasuwa Ma V | H36: 290050006 | I36: 29005000677043 | J36: Ramesh Adhikari | K36: /d]z clwsf/L | L36: M | M36: =IF(L36="M","k'?if","dlxnf") -> k'?if | N36: B/C | O36: Nepali | P36: g]kfnL | Q36: Nepali | R36: 49 | S36: 9841921810 | T36: 2046-4-3 | U36: 108527 | V36: Teacher | W36: MPhil | X36: Physics | Y36: Secondary | Z36: 3rd | AA36: Permanent | AB36: :yfoL
A37: Bagmati Province | B37: Rasuwa | D37: Gosaikunda Gaunpalika | F37: Rasuwa Ma V | H37: 290050006 | I37: 29005000677037 | J37: Kamana Ojha | K37: sfdgf cf]hf | L37: F | M37: =IF(L37="M","k'?if","dlxnf") -> dlxnf | N37: B/C | O37: Nepali | P37: g]kfnL | Q37: Nepali | R37: 51 | T37: 2050-7-11 | U37: 231015 | V37: Teacher | W37: Bachelors | Y37: Upper Basic | Z37: 3rd | AA37: Temporary | AB37: c:yfoL
A38: Bagmati Province | B38: Rasuwa | D38: Gosaikunda Gaunpalika | F38: Rasuwa Ma V | H38: 290050007 | I38: 29005000777002 | J38: Jun Maya Tamang | K38: h'g dfof tfdfË | L38: F | M38: =IF(L38="M","k'?if","dlxnf") -> dlxnf | N38: J | O38: Tamang | P38: tfdfË | Q38: Nepali | R38: 61 | S38: 9810180303 | T38: 2055-5-28 | U38: 230/74000135 | V38: Teacher | W38: SLC | Y38: ECD/PPC | Z38: 3rd | AA38: ECD Facilitator | AB38: O;L8L ;xof]uL
A39: Bagmati Province | B39: Rasuwa | D39: Gosaikunda Gaunpalika | F39: Rasuwa Ma V | H39: 290050007 | I39: 29005000777001 | J39: Lalkaji Tamang | K39: nfnsfhL tfdfË | L39: M | M39: =IF(L39="M","k'?if","dlxnf") -> k'?if | N39: J | O39: Tamang | P39: tfdfË | Q39: Nepali | R39: 62 | T39: 2035-4-15 | U39: 4744/556 | V39: Head Teacher | W39: Intermediate | X39: Education | Y39: Lower Basic | Z39: 3rd | AA39: Permanent | AB39: :yfoL
A40: Bagmati Province | B40: Rasuwa | D40: Gosaikunda Gaunpalika | F40: Rasuwa Ma V | H40: 290110001 | I40: 29011000177001 | J40: Phinjo Tamang | K40: lkmGhf] tfdfË | L40: M | M40: =IF(L40="M","k'?if","dlxnf") -> k'?if | N40: J | Q40: Nepali | R40: 63 | T40: 2040-5-20 | U40: 3375 | V40: Teacher | W40: SLC | Y40: Lower Basic | Z40: 3rd | AA40: Permanent | AB40: :yfoL
...

Sheet Sheet1
A1: क्र.सं. | B1: सहभागी शिक्षकको नाम थर | C1: विद्यालयको नाम | D1: विद्यालयको नाम | E1: विद्यालयको रहेको स्थानिय तह | F1: नियुक्ति मिति | G1: नियुक्तिको किसिम (स्थायी/अस्थायी) | H1: बाबुको नाम | I1: प्रदेश | J1: जिल्ला | K1: स्गथानिय तह | L1: वडा नं | M1: योग्यता | N1: सम्पर्क नं.
B2: अम्बिका कार्की | C2: =list!F2 -> Pra V Khamging | D2: k|f=la vflDuË | E2: गोसाँकुण्ड | G2: अस्थायी | I2: बाग्मती | J2: रसुवा | L2: 0 | N2: =list!S1 -> 9741086452
B3: तेम्बा तामाङ्ग | C3: =list!F3 -> Pra V Khamging | D3: k|f=la vflDuË | E3: गोसाँकुण्ड | G3: स्थायी | I3: बाग्मती | J3: रसुवा | L3: 0 | N3: =list!S2 -> 9741016525
B4: माया शेर्पा | C4: =list!F4 -> Pra V Khamging | D4: k|f=la vflDuË | E4: गोसाँकुण्ड | G4: स्थायी | I4: बाग्मती | J4: रसुवा | L4: 0 | N4: =list!S3 -> 9808712730
B5: कबिता न्यौपाने | C5: =list!F5 -> Lingling Pra V | D5: lnulnË | E5: गोसाँकुण्ड | G5: अस्थायी | I5: बाग्मती | J5: रसुवा | L5: 0 | N5: =list!S4 -> 9741161789
B6: निर्मल जंग शेर्पा | C6: =list!F6 -> Bhimali Pra V | D6: lednL k|f=ln | E6: गोसाँकुण्ड | G6: स्थायी | I6: बाग्मती | J6: रसुवा | L6: 0 | N6: =list!S5 -> 9860228865
B7: सुशिल कोइराला | C7: =list!F7 -> Bhimali Pra V | D7: lednL k|f=ln | E7: गोसाँकुण्ड | G7: स्थायी | I7: बाग्मती | J7: रसुवा | L7: 0 | N7: =list!S6 -> 9741035103
B8: तुल्सिंगी तामाङ्ग | C8: =list!F8 -> Bhimali Pra V | D8: lednL k|f=ln | E8: गोसाँकुण्ड | G8: स्थायी | I8: बाग्मती | J8: रसुवा | L8: 0 | N8: =list!S7 -> 0
B9: युना थोकरा | C9: =list!F9 -> Saraswati Adharbhut Vidyalaya | D9: ;/:jtL cfwf/e't laBfno | E9: गोसाँकुण्ड | G9: इसीडी सहयोगी | I9: बाग्मती | J9: रसुवा | L9: 0 | N9: =list!S8 -> 0
B10: उर्मिला लामा | C10: =list!F10 -> Saraswati Adharbhut Vidyalaya | D10: ;/:jtL cfwf/e't laBfno | E10: गोसाँकुण्ड | G10: स्थायी | I10: बाग्मती | J10: रसुवा | L10: 0 | N10: =list!S9 -> 9843404440
B11: कृष्ण बहादुर कुमाल | C11: =list!F11 -> Saraswati Adharbhut Vidyalaya | D11: ;/:jtL cfwf/e't laBfno | E11: गोसाँकुण्ड | G11: स्थायी | I11: बाग्मती | J11: रसुवा | L11: 0 | N11: =list!S10 -> 0
B12: युना तामाङ्ग | C12: =list!F12 -> Saraswati Adharbhut Vidyalaya | D12: ;/:jtL cfwf/e't laBfno | E12: गोसाँकुण्ड | G12: इसीडी सहयोगी | I12: बाग्मती | J12: रसुवा | L12: 0 | N12: =list!S11 -> 9823756146
B13: द्र्गा भत्त | C13: =list!F13 -> Saraswati Adharbhut Vidyalaya | D13: ;/:jtL cfwf/e't laBfno | E13: गोसाँकुण्ड | G13: स्थायी | I13: बाग्मती | J13: रसुवा | L13: 0 | N13: =list!S12 -> 0
... B94: श्रीप्रसाद शाह तेली | C94: =list!F94 -> 0 | D94: g]kfn /fli6«o cfwf/e't laBfno | E94: गोसाँकुण्ड | G94: स्थायी | I94: बाग्मती | J94: रसुवा | L94: 0 | N94: =list!S93 -> 9845786210

Sheet final_teacher_list
A1: क्र.सं. | B1: सहभागी शिक्षकको नाम थर | C1: विद्यालयको नाम | D1: विद्यालयको रहेको स्थानिय तह | E1: नियुक्ति मिति | F1: नियुक्तिको किसिम (स्थायी/अस्थायी) | G1: बाबुको नाम | H1: प्रदेश | I1: जिल्ला | J1: स्गथानिय तह | K1: वडा नं | L1: योग्यता | M1: सम्पर्क नं.
A2: 1 | B2: अम्बिका कार्की | C2: प्रा.बि खाम्गिङ्ग | D2: गोसाँकुण्ड | F2: अस्थायी | H2: बाग्मती | I2: रसुवा | K2: 0 | M2: 9741086452
A3: 2 | B3: तेम्बा तामाङ्ग | C3: प्रा.बि खाम्गिङ्ग | D3: गोसाँकुण्ड | F3: स्थायी | H3: बाग्मती | I3: रसुवा | K3: 0 | M3: 9741016525
A4: 3 | B4: माया शेर्पा | C4: प्रा.बि खाम्गिङ्ग | D4: गोसाँकुण्ड | F4: स्थायी | H4: बाग्मती | I4: रसुवा | K4: 0 | M4: 9808712730
A5: 4 | B5: कबिता न्यौपाने | C5: लिगलिङ्ग | D5: गोसाँकुण्ड | F5: अस्थायी | H5: बाग्मती | I5: रसुवा | K5: 0 | M5: 9741161789
A6: 5 | B6: निर्मल जंग शेर्पा | C6: भिमली प्रा.लि | D6: गोसाँकुण्ड | F6: स्थायी | H6: बाग्मती | I6: रसुवा | K6: 0 | M6: 9860228865
A7: 6 | B7: सुशिल कोइराला | C7: भिमली प्रा.लि | D7: गोसाँकुण्ड | F7: स्थायी | H7: बाग्मती | I7: रसुवा | K7: 0 | M7: 9741035103
A8: 7 | B8: तुल्सिंगी तामाङ्ग | C8: भिमली प्रा.लि | D8: गोसाँकुण्ड | F8: स्थायी | H8: बाग्मती | I8: रसुवा | K8: 0 | M8: 0
A9: 8 | B9: युना थोकरा | C9: सरस्वती आधारभुत बिद्यालय | D9: गोसाँकुण्ड | F9: इसीडी सहयोगी | H9: बाग्मती | I9: रसुवा | K9: 0 | M9: 0
A10: 9 | B10: उर्मिला लामा | C10: सरस्वती आधारभुत बिद्यालय | D10: गोसाँकुण्ड | F10: स्थायी | H10: बाग्मती | I10: रसुवा | K10: 0 | M10: 9843404440
A11: 10 | B11: कृष्ण बहादुर कुमाल | C11: सरस्वती आधारभुत बिद्यालय | D11: गोसाँकुण्ड | F11: स्थायी | H11: बाग्मती | I11: रसुवा | K11: 0 | M11: 0
A12: 11 | B12: युना तामाङ्ग | C12: सरस्वती आधारभुत बिद्यालय | D12: गोसाँकुण्ड | F12: इसीडी सहयोगी | H12: बाग्मती | I12: रसुवा | K12: 0 | M12: 9823756146
A13: 12 | B13: द्र्गा भत्त | C13: सरस्वती आधारभुत बिद्यालय | D13: गोसाँकुण्ड | F13: स्थायी | H13: बाग्मती | I13: रसुवा | K13: 0 | M13: 0
... A94: 93 | B94: श्रीप्रसाद शाह तेली | C94: नेपाल राष्ट्रिय आधारभुत बिद्यालय | D94: गोसाँकुण्ड | F94: स्थायी | H94: बाग्मती | I94: रसुवा | K94: 0 | M94: 9845786210

Sheet school_final
A1: schoolname | B1: address | C1: munvdc | D1: wardno | E1: district | F1: contact | G1: mobileno | H1: authorizeperson | I1: email | J1: website | K1: loginname | L1: spass | M1: remark
A2: प्रा.बि खाम्गिङ्ग | B2: गोसाँकुण्ड | C2: गोसाँकुण्ड | D2: 0 | E2: रसुवा | F2: 9741086452 | G2: 9741086452 | H2: अम्बिका कार्की | K2: 9741086452 | L2: 9741086452 | M2: Registered
A3: लिगलिङ्ग | B3: गोसाँकुण्ड | C3: गोसाँकुण्ड | D3: 0 | E3: रसुवा | F3: 9741161789 | G3: 9741161789 | H3: कबिता न्यौपाने | K3: 9741161789 | L3: 9741161789 | M3: Registered
A4: भिमली प्रा.लि | B4: गोसाँकुण्ड | C4: गोसाँकुण्ड | D4: 0 | E4: रसुवा | F4: 9860228865 | G4: 9860228865 | H4: निर्मल जंग शेर्पा | K4: 9860228865 | L4: 9860228865 | M4: Registered
A5: सरस्वती आधारभुत बिद्यालय | B5: गोसाँकुण्ड | C5: गोसाँकुण्ड | D5: 0 | E5: रसुवा | F5: 0 | G5: 0 | H5: युना थोकरा | K5: 0 | L5: 0 | M5: Registered
A6: रसुवा मा बि | B6: गोसाँकुण्ड | C6: गोसाँकुण्ड | D6: 0 | E6: रसुवा | F6: 9860600117 | G6: 9860600117 | H6: करपो तामाङ्ग | K6: 9860600117 | L6: 9860600117 | M6: Registered
A7: ग्यानजोती प्रा बि | B7: गोसाँकुण्ड | C7: गोसाँकुण्ड | D7: 0 | E7: रसुवा | F7: 9843308877 | G7: 9843308877 | H7: फुलमाया शर्मा | K7: 9843308877 | L7: 9843308877 | M7: Registered
A8: नेपाल राष्ट्रिय प्रा बि | B8: गोसाँकुण्ड | C8: गोसाँकुण्ड | D8: 0 | E8: रसुवा | F8: 9841115175 | G8: 9841115175 | H8: बिष्णु प्रसाद पौडेल | K8: 9841115175 | L8: 9841115175 | M8: Registered
A9: कोमिन श्यामेवानफेल मा बि | B9: गोसाँकुण्ड | C9: गोसाँकुण्ड | D9: 0 | E9: रसुवा | F9: 9841053323 | G9: 9841053323 | H9: किशोर कुमार पुरकोती | K9: 9841053323 | L9: 9841053323 | M9: Registered
A10: भिमसेन आधारभुत बिद्यालय | B10: गोसाँकुण्ड | C10: गोसाँकुण्ड | D10: 0 | E10: रसुवा | F10: 9842874717 | G10: 9842874717 | H10: ललित बोहरा | K10: 9842874717 | L10: 9842874717 | M10: Registered
A11: नेपाल राष्ट्रिय आधारभुत बिद्यालय | B11: गोसाँकुण्ड | C11: गोसाँकुण्ड | D11: 0 | E11: रसुवा | F11: 9865364305 | G11: 9865364305 | H11: शुभराज गुरुङ्ग | K11: 9865364305 | L11: 9865364305 | M11: Registered
A12: अरुणोदय प्रा बि | B12: गोसाँकुण्ड | C12: गोसाँकुण्ड | D12: 0 | E12: रसुवा | F12: 9845353474 | G12: 9845353474 | H12: फुपु यागिन तामाङ्ग | K12: 9845353474 | L12: 9845353474 | M12: Registered
A13: नेपाल राष्ट्रिय आधारभुत बिद्यालय दचेसा | B13: गोसाँकुण्ड | C13: गोसाँकुण्ड | D13: 0 | E13: रसुवा | F13: 9741340003 | G13: 9741340003 | H13: नारायनी आचार्य | K13: 9741340003 | L13: 9741340003 | M13: Registered

Sheet school_list
A1: schoolname | B1: address | C1: munvdc | D1: wardno | E1: district | F1: contact | G1: mobileno | H1: authorizeperson | I1: email | J1: website | K1: loginname | L1: spass | M1: remark
A2: प्रा.बि खाम्गिङ्ग | B2: गोसाँकुण्ड | C2: गोसाँकुण्ड | D2: 0 | E2: रसुवा | F2: 9741086452 | G2: 9741086452 | H2: अम्बिका कार्की | K2: 9741086452 | L2: 9741086452 | M2: Registered
A3: प्रा.बि खाम्गिङ्ग | B3: गोसाँकुण्ड | C3: गोसाँकुण्ड | D3: 0 | E3: रसुवा | F3: 9741016525 | G3: 9741016525 | H3: तेम्बा तामाङ्ग | K3: 9741016525 | L3: 9741016525 | M3: Registered
A4: प्रा.बि खाम्गिङ्ग | B4: गोसाँकुण्ड | C4: गोसाँकुण्ड | D4: 0 | E4: रसुवा | F4: 9808712730 | G4: 9808712730 | H4: माया शेर्पा | K4: 9808712730 | L4: 9808712730 | M4: Registered
A5: लिगलिङ्ग | B5: गोसाँकुण्ड | C5: गोसाँकुण्ड | D5: 0 | E5: रसुवा | F5: 9741161789 | G5: 9741161789 | H5: कबिता न्यौपाने | K5: 9741161789 | L5: 9741161789 | M5: Registered
A6: भिमली प्रा.लि | B6: गोसाँकुण्ड | C6: गोसाँकुण्ड | D6: 0 | E6: रसुवा | F6: 9860228865 | G6: 9860228865 | H6: निर्मल जंग शेर्पा | K6: 9860228865 | L6: 9860228865 | M6: Registered
A7: भिमली प्रा.लि | B7: गोसाँकुण्ड | C7: गोसाँकुण्ड | D7: 0 | E7: रसुवा | F7: 9741035103 | G7: 9741035103 | H7: सुशिल कोइराला | K7: 9741035103 | L7: 9741035103 | M7: Registered
A8: भिमली प्रा.लि | B8: गोसाँकुण्ड | C8: गोसाँकुण्ड | D8: 0 | E8: रसुवा | F8: 0 | G8: 0 | H8: तुल्सिंगी तामाङ्ग | K8: 0 | L8: 0 | M8: Registered
A9: सरस्वती आधारभुत बिद्यालय | B9: गोसाँकुण्ड | C9: गोसाँकुण्ड | D9: 0 | E9: रसुवा | F9: 0 | G9: 0 | H9: युना थोकरा | K9: 0 | L9: 0 | M9: Registered
A10: सरस्वती आधारभुत बिद्यालय | B10: गोसाँकुण्ड | C10: गोसाँकुण्ड | D10: 0 | E10: रसुवा | F10: 9843404440 | G10: 9843404440 | H10: उर्मिला लामा | K10: 9843404440 | L10: 9843404440 | M10: Registered
A11: सरस्वती आधारभुत बिद्यालय | B11: गोसाँकुण्ड | C11: गोसाँकुण्ड | D11: 0 | E11: रसुवा | F11: 0 | G11: 0 | H11: कृष्ण बहादुर कुमाल | K11: 0 | L11: 0 | M11: Registered
A12: सरस्वती आधारभुत बिद्यालय | B12: गोसाँकुण्ड | C12: गोसाँकुण्ड | D12: 0 | E12: रसुवा | F12: 9823756146 | G12: 9823756146 | H12: युना तामाङ्ग | K12: 9823756146 | L12: 9823756146 | M12: Registered
A13: सरस्वती आधारभुत बिद्यालय | B13: गोसाँकुण्ड | C13: गोसाँकुण्ड | D13: 0 | E13: रसुवा | F13: 0 | G13: 0 | H13: द्र्गा भत्त | K13: 0 | L13: 0 | M13: Registered
... A94: नेपाल राष्ट्रिय आधारभुत बिद्यालय | B94: गोसाँकुण्ड | C94: गोसाँकुण्ड | D94: 0 | E94: रसुवा | F94: 9845786210 | G94: 9845786210 | H94: श्रीप्रसाद शाह तेली | K94: 9845786210 | L94: 9845786210 | M94: Registered
